Workbook

Sheet Nation Wise Summary
A1: Nation | B1: Continent | C1: Neighboring Nations | D1: Form of Governence | E1: Head of Nation | F1: Gender of Head | G1: Title | H1: Leading Party | I1: Last Elected Year | J1: Tenure | K1: Time | L1: Winning Constituency | M1: Residing State | N1: Ceremonial Head | O1: Title of Ceremonial Head | P1: Title | Q1: Last Elected Year | R1: Tenure | S1: Protests and unrests in 2025 | T1: Current Political Stability | U1: Total Land Area | V1: Total Inland Water Area | W1: Population in 2025 | X1: Population in 2024 | Y1: Population Rate | Z1: Population Density | AA1: Urban Population | AB1: Urban Population Density | AC1: Rural Population | AD1: Rural Population density | AE1: Currency | AF1: Exchange Rate wrt INR | AG1: Current Total Income | AH1: GDP in 2025 | AI1: GDP in 2024 | AJ1: Rate | AK1: Per Capita Income | AL1: Top five Key sources of income | AM1: Safety Index | AN1: Education Index | AO1: Key Notes
A2: India | B2: Asia | C2: Bangladesh, China, Pakistan, Afghanistan, Nepal, Myanmar, Bhutan, Sri Lanka, Maldives | D2: Federal Parliamentary Democratic Republic | E2: Narendra Modi | F2: Male | G2: Prime Minister | H2: Bhartiya Janata Party | I2: 2024 | J2: 2014-19; 2019-24, 2024-+ | K2: 12 | L2: Varanasi | M2: Gujarat | N2: Droupadi Murmu | O2: Female | P2: President | Q2: 2022 | R2: 2022-+ | U2: 2973193 | Y2: =IF(X2="", "", ((W2-X2)/X2)*100) | AJ2: =IF(AI2="", "", ((AH2-AI2)/AI2)*100) | AO2: 1. 140 million years ago, Madagascar and India broke from Africa. While Madagascar stayed in the African vicinity, India rashed past and joined with the Eurasian plate creating Himalayas and Tibetan plateau. Due to its complete fusion with the Asian landmass and no connection to African landmass, India is strictly an Asian country rather than Asia and Africa. 2. Afghanistan is the border of India which is shortest of 106km through Ladakh, but that part comes in the POK which is legally the part of India. 2. Maritime Borders between India and Indonesia is not a conceptual idea, but a legal binding and mapped out as the two nations signed formal India- Indonesia Maritime Boundary Agreements in 1974 and 1977. These treaties precisely delimited the continental shelf and maritime boundaries stretching nearly 300 nautical miles across the Andaman Sea and the Indian Ocean.
A3: China | B3: Asia | C3: India, Mongolia, Russia, North Korea, Kazakhstan, Kyrgyzstan, Tajikistan, Afghanistan, Pakistan, Nepal, Bhutan, Myanmar, Laos, Vietnam, South Korea, Japan, Phillipines, Indonesia | D3: Unitary Socialist One-Party Republic | E3: Xi Jinping | F3: Male | G3: President | H3: Chinese Communist Party | I3: 2023 | J3: 2012-2013; 2013-2017; 2018-2023; 2023-+ | K3: 13 | L3: Jiangsu | M3: Shaanxi | N3: NA | O3: NA | P3: NA | Q3: NA | R3: NA | U3: 9388211 | Y3: =IF(X3="", "", ((W3-X3)/X3)*100) | AJ3: =IF(AI3="", "", ((AH3-AI3)/AI3)*100) | AO3: 1. Taiwan operates as a separate, de facto independent country, whereas Hong Kong and Macao are officially part of China but operates as highly autonomous territories. Taiwan functions exactly like an independent country as it has its own democratically elected president, parliament, constitution, passport, currency, and millitary forces. The Chinese government has never ruled the island in the modern era. But the PRC claims Taiwan is a breakaway province that must be reunified with the mainland. China considers Taiwan its part because of a combination of historical claims, the outcome of Chinese Civil War, and the legal framework established in its constitution - In 1949, the Chinese Civil War ended with the chinese Communist Party winning control of mainland China as they established PRC while the defeated Nationalist governament - Kuomintang, led by Chiang Kai-shek, fled to Taiwan as they maintained the island's existing government, known as the Republic of China. China gained administrative control in the island in 1963 during Qing Dynasty but lost it to Japan in 1895 after losing the First Sino-Japanese War, which was handed back to China after the defeat of Japan in WW2 in 1945. 2. China has the highes number of neighbors considering the land and maritime boundaries - 20
A4: United States | B4: North America | C4: Canada, Mexico, Russia, Bahamas, Cuba, UK, Dominican Republic, Samoa, New Zealand, Micronesia | D4: Federal Constitutional Republic and Representative Democracy | E4: Donald Trump | F4: Male | G4: President | H4: Republican Party | I4: 2025 | J4: 2017-2021; 2025-+ | K4: 6 | L4: Pan | M4: Florida | N4: NA | O4: NA | P4: NA | Q4: NA | R4: NA | U4: 9147120 | Y4: =IF(X4="", "", ((W4-X4)/X4)*100) | AJ4: =IF(AI4="", "", ((AH4-AI4)/AI4)*100) | AO4: 1. USA and Russia is divided by the Bering Strait in Alaska while Cuba and Bahamas are joined to USA thorugh Florida. UK and USA share boundaries through British Virgin Islands while Dominican Republic is seperated to USA through Puerto Rico. Venezuela is connected to US through US Virgin Islands while Samoa and New Zealand is connected through American Samoa and Micronesia through Guam. 2. US and Canada border is the longest land border between any two countries in the world
A5: Indonesia | B5: Asia | C5: China, Malaysia, Papua New Guinea, Timor-Leste, Australia, Palau, Phillipines, Singapore, Thailand, Vietnam | D5: Unitary Presidential Constitutional Republic | E5: Prabowo Subianto | F5: Male | G5: President | H5: Gerindra Party (Great Indonesia Movement Party) | I5: 2024 | J5: 2024-+ | K5: 2 | L5: Pan | M5: Jakarta | N5: NA | O5: NA | P5: NA | Q5: NA | R5: NA | U5: 1811569 | Y5: =IF(X5="", "", ((W5-X5)/X5)*100) | AJ5: =IF(AI5="", "", ((AH5-AI5)/AI5)*100) | AO5: 1. The relation between Indonesia and India is quiet wrongly interpretted when it comes to Maritime boundaries - normally India considers Sri Lanka and Maldives as its maritime neighbours, but the confusion arise when a fact is seen that there is a maritime boundary between India's Andaman and Nicobar Islands and Indonesia's Sumatra Island. But as the standard maps focus primarily on the mainland core of India and Indian subcontinent, Indonesia is not considered as India's maritime neighbour. Technically India and Indonesia have maritime boirder as the Indira Point of the Andaman and Nicobar Island in India is just 400 nautical miles away from the Aceh region in Sumatra in north Indonesia, while the Rondo Island near Great Nicobar is just 80-90 nautical miles away from Indonesia's Banda Aceh
A6: Pakistan | B6: Asia | C6: India, China, Afghanistan, Iran, Oman | D6: Federal Parliamentary Republic | E6: Shehbaz Sharif | F6: Male | G6: Prime Minister | H6: Pakistan Muslim League - Nawaz | I6: 2024 | J6: 2022-2023; 2024-+ | K6: 4 | L6: Lahore | M6: Punjab Province | N6: Asif Ali Zardari | O6: Male | P6: President | Q6: 2024 | R6: 2008-2013; 2024-+ | Y6: =IF(X6="", "", ((W6-X6)/X6)*100) | AJ6: =IF(AI6="", "", ((AH6-AI6)/AI6)*100)
A7: Nigeria | B7: Africa | C7: Niger, Chad, Cameroon, Benin, Equitorial Guinea, Sao Tome and Principe, Ghana | D7: Federal Parliamentary Republic | E7: Bola Ahmed Tinubu | F7: Male | G7: President | H7: All Progressives Congress | I7: 2023 | J7: 2023-+ | K7: 3 | L7: Pan | M7: Lagos | N7: NA | O7: NA | P7: NA | Q7: NA | R7: NA | Y7: =IF(X7="", "", ((W7-X7)/X7)*100) | AJ7: =IF(AI7="", "", ((AH7-AI7)/AI7)*100)
A8: Brazil | B8: South America | C8: Venezuela, Guyana, Suriname, France, Colombia, Peru, Bolivia, Paraguay, Argentina, Uruguay | D8: Federal Constitutional Republic and Representative Democracy | E8: Luiz Inacio Lula da Silva | F8: Male | G8: President | H8: Partido dos Trabalhadores (Workers' Party) | I8: 2023 | J8: 2003-2007; 2007-2011; 2023-+ | K8: 3 | L8: Pan | M8: Pernambuco | N8: NA | O8: NA | P8: NA | Q8: NA | R8: NA | Y8: =IF(X8="", "", ((W8-X8)/X8)*100) | AJ8: =IF(AI8="", "", ((AH8-AI8)/AI8)*100) | AO8: 1. Brazil officially shares a land border with France because French Guiana is an overseas department and an integral part of France.
A9: Bangladesh | B9: Asia | C9: India, Myanmar | D9: Unitary Parliamentary Representative Democratic Republic | E9: Tarique Rahman | F9: Male | G9: Prime Minister | H9: Bangladesh Nationalist Party | I9: 2026 | J9: 2026-+ | K9: 1 | L9: Dhaka | M9: Dhaka | N9: Mirza Fakhrul Islam Alamgir | O9: Male | P9: President | Q9: 2026 | R9: 2026-+ | Y9: =IF(X9="", "", ((W9-X9)/X9)*100) | AJ9: =IF(AI9="", "", ((AH9-AI9)/AI9)*100)
A10: Russia | B10: Europe and Asia | C10: China, US, Norway, Finland, Estonia, Latvia, Lithuania, Poland, Belarus, Ukraine, Georgia, Azerbaijan, Kazakhstan, Mongolia, North Korea, Japan, Turkmenistan, Iran | D10: Federal Semi-Presidential Republic | E10: Vladimir Putin | F10: Male | G10: President | H10: United Russia | I10: 2012 | J10: 1999-2008; 2012-+ | K10: 14 | L10: Pan | M10: St.Petersburg | N10: NA | O10: NA | P10: NA | Q10: NA | R10: NA | Y10: =IF(X10="", "", ((W10-X10)/X10)*100) | AJ10: =IF(AI10="", "", ((AH10-AI10)/AI10)*100) | AO10: 1. Russia's 77% land is in Asia while its 75-80% population is in Europe. 2. Russia and China are tied for the countries with most national neighbours through land borders being 14. 3. Even though Uzbekistan, Krygyzstan, Turkmenistan, and Tajikistan is normally considered associated with Russia because of their Soiviet connections, they are not neighbours as four are separated from Russia through Kazakhstan. 3. Poland and Lithuania does not have a physical visual land border with Russia, but because of a region acquired in the Baltic Sea called Kalingrad, the two became Russia's border.
A11: Ethiopia | B11: Africa | C11: Eritrea, Djibouti, Somalia, Kenya, South Sudan, Sudan | D11: Federal Parliamentary Republic | E11: Abiy Ahmed | F11: Male | G11: Prime Minister | H11: Prosperity Party | I11: 2021 | J11: 2018-2021; 2021-+ | K11: 5 | L11: Beshasha | M11: Beshasha | N11: Taye Atake Selassie | O11: Male | P11: President | Q11: 2024 | R11: 2024-+ | Y11: =IF(X11="", "", ((W11-X11)/X11)*100) | AJ11: =IF(AI11="", "", ((AH11-AI11)/AI11)*100)
A12: Mexico | B12: North America | C12: US, Guatemala, Belize, Cuba, Honduras | D12: Federal Presidential Representative Democratic Republic | E12: Claudia Sheinbaum | F12: Female | G12: President | H12: Morena (Movimiento de Regeneracion Nacional) | I12: 2024 | J12: 2024-+ | K12: 2 | L12: Pan | M12: Mexico City | N12: NA | O12: NA | P12: NA | Q12: NA | R12: NA | Y12: =IF(X12="", "", ((W12-X12)/X12)*100) | AJ12: =IF(AI12="", "", ((AH12-AI12)/AI12)*100)
A13: Japan | B13: Asia | C13: China, South Korea, Russia, Phillipines, North Korea | D13: Unitary Constitutional Monarchy with a Parliamentary Democracy | E13: Sanae Takaichi | F13: Female | G13: Prime Minister | H13: Liberal Democratic Party | I13: 2025 | J13: 2025-+ | K13: 1 | L13: Nara | M13: Nara | N13: Naruhito | O13: Male | P13: Emperor | Q13: 2019 | R13: 2019-+ | Y13: =IF(X13="", "", ((W13-X13)/X13)*100) | AJ13: =IF(AI13="", "", ((AH13-AI13)/AI13)*100) | AO13: 1. Japan has no land borders as it is an island nation. It falls under a small category of nations that have countries like UK, Sri Lanka, Maldives, Australia, New Zealan, Iceland etc. 2 .The case between US and Japan is exactly same as India-Indonesia maritime border as the US territory of Northern Mariana Islands sits far west from the American mainland which directly meets the Japan's eastern Ogasawara island chain - just like how India's Andaman and Nicobar Islands is in direct vicinity (just 300 to 400 nautical miles away) from the Aceh region of northern Indonesia.
A14: Egypt | B14: Africa and Asia | C14: Libya, Sudan, Israel, Palestine, Saudi Arabia, Jordan, Greece, Cyprus | D14: Unitary Semi-Presidential Republic | E14: Abdel Fattah el-Sisi | F14: Male | G14: President | H14: Unaffiliated | I14: 2024 | J14: 2014-2018; 2018-2024; 2024-+ | K14: 2 | L14: Pan | M14: Cairo | N14: Mostafa Madbouly | O14: Male | P14: Prime Minister | Q14: 2024 | R14: 2018-2024; 2024-+ | Y14: =IF(X14="", "", ((W14-X14)/X14)*100) | AJ14: =IF(AI14="", "", ((AH14-AI14)/AI14)*100) | AO14: 1. Majority part of Egypt is in Africa while a small portion of Sinai Peninsular is in Asia.
A15: Phillipines | B15: Asia | C15: China, Indonesia, Japan, Palau, Malaysia, Vietnam | Y15: =IF(X15="", "", ((W15-X15)/X15)*100) | AJ15: =IF(AI15="", "", ((AH15-AI15)/AI15)*100)
A16: DR Congo | B16: Africa | C16: CAR, South Sudan, Uganda, Rwanda, Burundi, Tanzania, Zambia, Angola, Congo | Y16: =IF(X16="", "", ((W16-X16)/X16)*100) | AJ16: =IF(AI16="", "", ((AH16-AI16)/AI16)*100)
A17: Vietnam | B17: Asia | C17: China, Indonesia, Philippines, Laos, Cambodia, Thailand, Malaysia | Y17: =IF(X17="", "", ((W17-X17)/X17)*100) | AJ17: =IF(AI17="", "", ((AH17-AI17)/AI17)*100)
A18: Iran | B18: Asia | C18: Pakistan, Iraq, Turkey, Armenia, Azerbaijan, Turkmenistan, Afghanistan, Saudi Arabia, UAE, Qatar, Kuwait, Bahrain, Oman, Russia | Y18: =IF(X18="", "", ((W18-X18)/X18)*100) | AJ18: =IF(AI18="", "", ((AH18-AI18)/AI18)*100)
A19: Turkey | B19: Asia and Europe | C19: Iran, Greece, Bulgaria, Georgia, Armenia, Azerbaijan, Iraq, Syria, Ukraine, Romania, Cyprus, | Y19: =IF(X19="", "", ((W19-X19)/X19)*100) | AJ19: =IF(AI19="", "", ((AH19-AI19)/AI19)*100) | AO19: 1. About 97% of the country is in West Asia while remaining part is in southern Europe. 2. The case between Turkey and Russia is same as that of India-Indonesia - Linked by Black Sea Agreement in 1978 in case of Russia-Turkey just like linked by Great Channel Agreements in 1974-77 between India-Indoesia as they both have legal EEZ touch
A20: Germany | B20: Europe | C20: Denmark, Poland, Czech Republic, France, Luxembourg, Belgium, Netherlands, Sweden, UK, Austria, Switzerland | Y20: =IF(X20="", "", ((W20-X20)/X20)*100) | AJ20: =IF(AI20="", "", ((AH20-AI20)/AI20)*100)
A21: Tanzania | B21: Africa | C21: DR Congo, Kenya, Uganda, Rwanda, Burundi, Zambia, Malawi, Mozambique, Comoros, Seychelles | Y21: =IF(X21="", "", ((W21-X21)/X21)*100) | AJ21: =IF(AI21="", "", ((AH21-AI21)/AI21)*100)
A22: Thailand | B22: Asia | C22: Indonesia, Vietnam, Myanmar, Laos, Cambodia, Malaysia | Y22: =IF(X22="", "", ((W22-X22)/X22)*100) | AJ22: =IF(AI22="", "", ((AH22-AI22)/AI22)*100) | AO22: 1. Case of Thailand is exactly the same as Indonesia for India as through Andaman and Nicobar Islands.
A23: United Kingdom | B23: Europe | C23: US, Germany, Ireland, France, Belgium, Netherlands, Denmark, Norway | Y23: =IF(X23="", "", ((W23-X23)/X23)*100) | AJ23: =IF(AI23="", "", ((AH23-AI23)/AI23)*100)
A24: France | B24: Europe | C24: Germany, Brazil, UK, Spain, Belgium, Switzerland, Italy, Luxembourg, Andorra, Monaco | Y24: =IF(X24="", "", ((W24-X24)/X24)*100) | AJ24: =IF(AI24="", "", ((AH24-AI24)/AI24)*100) | AO24: 1. France shares maritime boundaries with approximately 30 different countries across every major ocean. UK, Belgium, Italy, Spain, and Monaco through organic Atlantic Ocean border, while Canada, Antigua and Berbuda, Barbados, Dominica, Saint Lucia, St. Vincent and the Grenadines, Venezuela, Netherlands, and part of UK from its possession of American territories like Saint Pierre and Miquelon, Guadelope, Martinique, Saint Martini, and Saint Barthelemy; South American Maritime neighbours of Brazil and Suriname through French Guinea, Indian Ocean neighbours of Comoros, Madagascar, Mauritius, Seychelles, Mozambique through acquisition of islands like Reunion, Mayotte, and the French Southern and Antarctic Lands, and Oceania neighbours of Australia, Fiji, Kiribati, Papua New Guinea thorugh French Polynesia, New Caledonia, and Wallis and Futuna, For New Zealand as the maritime neighbour of France though Tokelau and Cook Islands.
A25: South Africa | B25: Africa | C25: Namibia, Botswana, Zimbabwe, Mozambique, Eswatini, Lesotho | Y25: =IF(X25="", "", ((W25-X25)/X25)*100) | AJ25: =IF(AI25="", "", ((AH25-AI25)/AI25)*100) | AO25: 1. South Africa shares a border with france through its acquired region of subantarctic region of Prince Edward Islands - Marion Island and Prince Edward Island.
A26: Italy | B26: Europe | C26: France, Switzerland, Austria, Slovenia, San Marino, Croatia, Albania, Montenegro, Greece, Malta, Tunisia, Libya, Algeria, Spain, Holy See | Y26: =IF(X26="", "", ((W26-X26)/X26)*100) | AJ26: =IF(AI26="", "", ((AH26-AI26)/AI26)*100) | AO26: 1. San Marino and Vatican City are enclaved nations in italy. Vatican City is an independent city-state entirely surrounded by the city of Rome.
A27: Kenya | B27: Africa | C27: Ethiopia, Tanzania, Uganda, South Sudan, Somalia | AJ27: =IF(AI27="", "", ((AH27-AI27)/AI27)*100) | AO27: 1. India is officially recognized as a maritime neighbour of Kenya through a formal bilateral framework called the BAHARI Joint Vision Statement issued by Indian Ministry of External Affairs. Signed during the Kenya President William Ruto's state visit to India - BAHARI means outside in Hindi as in outside the scope of traditional definition of the international boundary of India, and BAHARI meaning ocean in Swahili which means is the cross-ocean facing nation to Kenya.
A28: Myanmar | B28: Asia | C28: India, China, Bangladesh, Thailand, Laos | AJ28: =IF(AI28="", "", ((AH28-AI28)/AI28)*100)
A29: Colombia | B29: South America | C29: Brazil, Panama, Venezuela, Peru, Ecuador, Costa Rica, Nicaragua, Honduras, Jamaica, Dominican Republic | AJ29: =IF(AI29="", "", ((AH29-AI29)/AI29)*100)
A30: Sudan | B30: Africa | C30: Ethiopia, Egypt, Libya, Chad, CAR, South Sudan, Eritrea, Saudi Arabia | AJ30: =IF(AI30="", "", ((AH30-AI30)/AI30)*100)
A31: Uganda | B31: Africa | C31: DR Congo, Tanzania, Kenya, South Sudan, Rwanda | AJ31: =IF(AI31="", "", ((AH31-AI31)/AI31)*100)
A32: South Korea | B32: Asia | C32: China, Japan, North Korea | AJ32: =IF(AI32="", "", ((AH32-AI32)/AI32)*100)
A33: Algeria | B33: Africa | C33: Italy, Tunisia, Libya, Niger, Mali, Mauritania, Morocco, Spain | AJ33: =IF(AI33="", "", ((AH33-AI33)/AI33)*100)
A34: Iraq | B34: Asia | C34: Iran, Turkey, Syria, Jordan, Saudi Arabia, Kuwait | AJ34: =IF(AI34="", "", ((AH34-AI34)/AI34)*100)
A35: Spain | B35: Europe | C35: France, Italy, Algeria, Portugal, Andorra, Morocco | AJ35: =IF(AI35="", "", ((AH35-AI35)/AI35)*100) | AO35: 1. Due to the presence of Canary Islands, Spain shares an Exclusive Economic Zone bounday with Mauritania and Cape Verde. 2. UK has a boundary with Spain as the former has a colony in the form of Gibraltar at the southern tip of the Iberian Peninsula.
A36: Argentina | B36: South America | C36: Brazil, Chile, Bolivia, Paraguay, Uruguay | AJ36: =IF(AI36="", "", ((AH36-AI36)/AI36)*100) | AO36: 1. Argentina shares a maritime border with UK through Falkland Islands.
A37: Afghanistan | B37: Asia | C37: India, China, Pakistan, Iran, Tajikistan, Turkmenistan, Uzbekistan | AJ37: =IF(AI37="", "", ((AH37-AI37)/AI37)*100)
A38: Yemen | B38: Asia | C38: Saudi Arabia, Oman, Djibouti, Eritrea, Somalia | AJ38: =IF(AI38="", "", ((AH38-AI38)/AI38)*100)
A39: Canada | B39: North America | C39: US, Denmark | AJ39: =IF(AI39="", "", ((AH39-AI39)/AI39)*100) | AO39: 1. Denmark shares a maritime boundary and a tiny land border on the divided Hans Island in the Arctic. Hans Island - also known as Tartupaluk in Greelandic is a small uninhabitated Arctic Island that is famously split between Canada and the kingdom of Denmark.
A40: Angola | B40: Africa | C40: DR Congo, Namibia, Zambia, Congo | AJ40: =IF(AI40="", "", ((AH40-AI40)/AI40)*100)
...

Sheet Nation Non-Social Pop Demograph
A1: Nation | B1: Current Population | C1: Current Urban Population | D1: Urban Population Percent | E1: Male Population | F1: Female Population | G1: Other Gender Population | H1: Sex Ratio | I1: Recordeed Sex Rate | J1: Pre-adolescent Population (< 19) | K1: Male Pre-adolescent Population | L1: Female Pre-adolescent Population | M1: Female School Attendence Percent | N1: Young adolescnet population (19-30) | O1: Male Young-adolescent Population | P1: Female Young-adolescent Population | Q1: Female College Attendence Percent | R1: Working population (25-60) | S1: Employment Rate | T1: Male Working Population | U1: Male Employment | V1: Male Working Percent | W1: Female Working Population | X1: Female Employment | Y1: Female Working Percent | Z1: Senior Population (60 <)
A2: India | B2: 1479537695 | C2: 555299296 | D2: =IF(B2="", "", (C2/B2)*100) -> 37.531946 | E2: 761119796 | F2: 715505781 | G2: =B2-(E2+F2) -> 2912118 | H2: =IF(F2="", "", E2/F2) -> 1.0637507 | I2: =1/0.94 -> 1.0638298 | J2: 458656685 | K2: 239328000 | L2: 219328685 | M2: =IF(J2="", "", (L2/J2)*100) -> 47.819795 | N2: 329936905 | O2: 171897127 | P2: 158039778 | Q2: =IF(N2="", "", (P2/N2)*100) -> 47.9 | R2: 668741200 | S2: 52.8 | T2: 369145259 | U2: 402000000 | V2: =(U2/T2)*100 -> 108.90022 | W2: 346360522 | X2: 164000000 | Y2: =(X2/W2)*100 -> 47.349507 | Z2: 173200000
A3: China | B3: 1412155898 | C3: =(949000000+953175600+970433085)/3 -> 9.5753623e+08 | D3: =IF(B3="", "", (C3/B3)*100) -> 67.806694 | E3: =(717000000+718810000)/2 -> 717905000 | F3: 694105287 | G3: =B3-(E3+F3) -> 145611 | H3: =IF(F3="", "", E3/F3) -> 1.0342883 | I3: 1.036 | J3: =(278900000+298000000)/2 -> 288450000 | K3: =(149400000+158000000)/2 -> 153700000 | L3: 129500000 | M3: =IF(J3="", "", (L3/J3)*100) -> 44.895129 | N3: 202300000 | O3: 106170000 | P3: 91830000 | Q3: =IF(N3="", "", (P3/N3)*100) -> 45.392981 | R3: 737307267 | S3: 61.57 | T3: 381839779 | U3: 407175000 | V3: =(U3/T3)*100 -> 106.63504 | W3: 352467488 | X3: 320000000 | Y3: =(X3/W3)*100 -> 90.788516 | Z3: 323380000
A4: United States | B4: 349529545 | C4: =(284043692+265149027)/2 -> 2.7459636e+08 | D4: =IF(B4="", "", (C4/B4)*100) -> 78.561702 | E4: 175400000 | F4: 173636381 | G4: =B4-(E4+F4) -> 493164 | H4: =IF(F4="", "", E4/F4) -> 1.010157 | I4: 1.01015 | J4: 72021348 | K4: 36893704 | L4: 35127644 | M4: =IF(J4="", "", (L4/J4)*100) -> 48.773933 | N4: 53850000 | O4: 27517350 | P4: 26332650 | Q4: =IF(N4="", "", (P4/N4)*100) -> 48.9 | R4: 158821224 | S4: 59.1 | T4: 80821114 | U4: 85734000 | V4: =(U4/T4)*100 -> 106.07872 | W4: 78000110 | X4: 82585000 | Y4: =(X4/W4)*100 -> 105.87806 | Z4: 79547743
A5: Indonesia | B5: 288436855 | C5: 173513303 | D5: =IF(B5="", "", (C5/B5)*100) -> 60.156426 | E5: 144610243 | F5: 143276540 | G5: =B5-(E5+F5) -> 550072 | H5: =IF(F5="", "", E5/F5) -> 1.0093086 | I5: 1.0093 | J5: 83670410 | K5: 42912414 | L5: 40757996 | M5: =IF(J5="", "", (L5/J5)*100) -> 48.712557 | N5: 53421860 | O5: 27330770 | P5: 26091090 | Q5: =IF(N5="", "", (P5/N5)*100) -> 48.839726 | R5: 142574415 | S5: 66 | T5: 72551320 | U5: 88975410 | V5: =(U5/T5)*100 -> 122.63789 | W5: 70023095 | X5: 58694590 | Y5: =(X5/W5)*100 -> 83.821759 | Z5: 34525892
A6: Pakistan | B6: 260010725 | C6: =(100877063+89987063+93750000)/3 -> 94871375 | D6: =IF(B6="", "", (C6/B6)*100) -> 36.487485 | E6: =(131270000+127842594+124320000)/3 -> 1.2781086e+08 | F6: =(128031202+123761990+117150000)/3 -> 122981064 | G6: =B6-(E6+F6) -> 9218796.3 | H6: =IF(F6="", "", E6/F6) -> 1.0392727 | I6: 1.0253 | J6: =(109510765+117000000+112000000)/3 -> 1.1283692e+08 | K6: 58099978 | L6: 54370121 | M6: =IF(J6="", "", (L6/J6)*100) -> 48.18469 | Q6: =IF(N6="", "", (P6/N6)*100)
A7: Nigeria | D7: =IF(B7="", "", (C7/B7)*100) | H7: =IF(F7="", "", E7/F7) | M7: =IF(J7="", "", (L7/J7)*100) | Q7: =IF(N7="", "", (P7/N7)*100)
A8: Brazil | D8: =IF(B8="", "", (C8/B8)*100) | H8: =IF(F8="", "", E8/F8) | M8: =IF(J8="", "", (L8/J8)*100) | Q8: =IF(N8="", "", (P8/N8)*100)
A9: Bangladesh | D9: =IF(B9="", "", (C9/B9)*100) | H9: =IF(F9="", "", E9/F9) | M9: =IF(J9="", "", (L9/J9)*100) | Q9: =IF(N9="", "", (P9/N9)*100)
A10: Russia | D10: =IF(B10="", "", (C10/B10)*100) | H10: =IF(F10="", "", E10/F10) | M10: =IF(J10="", "", (L10/J10)*100) | Q10: =IF(N10="", "", (P10/N10)*100)
A11: Ethiopia | D11: =IF(B11="", "", (C11/B11)*100) | H11: =IF(F11="", "", E11/F11) | M11: =IF(J11="", "", (L11/J11)*100) | Q11: =IF(N11="", "", (P11/N11)*100)
A12: Mexico | D12: =IF(B12="", "", (C12/B12)*100) | H12: =IF(F12="", "", E12/F12) | M12: =IF(J12="", "", (L12/J12)*100) | Q12: =IF(N12="", "", (P12/N12)*100)
A13: Japan | D13: =IF(B13="", "", (C13/B13)*100) | H13: =IF(F13="", "", E13/F13) | M13: =IF(J13="", "", (L13/J13)*100) | Q13: =IF(N13="", "", (P13/N13)*100)
A14: Egypt | D14: =IF(B14="", "", (C14/B14)*100) | H14: =IF(F14="", "", E14/F14) | M14: =IF(J14="", "", (L14/J14)*100) | Q14: =IF(N14="", "", (P14/N14)*100)
A15: Phillipines | D15: =IF(B15="", "", (C15/B15)*100) | H15: =IF(F15="", "", E15/F15) | M15: =IF(J15="", "", (L15/J15)*100) | Q15: =IF(N15="", "", (P15/N15)*100)
A16: DR Congo | D16: =IF(B16="", "", (C16/B16)*100) | H16: =IF(F16="", "", E16/F16) | M16: =IF(J16="", "", (L16/J16)*100) | Q16: =IF(N16="", "", (P16/N16)*100)
A17: Vietnam | D17: =IF(B17="", "", (C17/B17)*100) | H17: =IF(F17="", "", E17/F17) | M17: =IF(J17="", "", (L17/J17)*100) | Q17: =IF(N17="", "", (P17/N17)*100)
A18: Iran | D18: =IF(B18="", "", (C18/B18)*100) | H18: =IF(F18="", "", E18/F18) | M18: =IF(J18="", "", (L18/J18)*100) | Q18: =IF(N18="", "", (P18/N18)*100)
... A197: Holy See | D197: =IF(B197="", "", (C197/B197)*100) | H197: =IF(F197="", "", E197/F197) | M197: =IF(J197="", "", (L197/J197)*100) | Q197: =IF(N197="", "", (P197/N197)*100)

Sheet Nation-Wide Education Seg
A1: Nation | B1: Literacy Rate | C1: No. Of Schools | D1: Percentage of Private Schools | E1: School Density | F1: School-on-population density | G1: School-on-preteen-population density | H1: No. of Colleges and University | I1: Percentage of Private Universities | J1: Percentage of Private Colleges | K1: College density | L1: College-on-population density | M1: College-on-student-population density | N1: No. of Teachers in schools | O1: No. of Teachers in Colleges/ Univ\ | P1: Teachers/School Students | Q1: Teachers / College Students
A2: India | B2: 80.9 | C2: 1466682 | D2: =(22.6+23)/2 -> 22.8 | E2: =IF('Nation Wise Summary'!U2="", "", (C2/'Nation Wise Summary'!U2)*100) -> 49.330198 | F2: =IF('Nation Non-Social Pop Demograph'!B2="", "", ('Nation-Wide Education Seg'!C2/'Nation Non-Social Pop Demograph'!B2)*10000) -> 9.9131101 | G2: =IF('Nation Non-Social Pop Demograph'!J2="", "", ('Nation-Wide Education Seg'!C2/'Nation Non-Social Pop Demograph'!J2)*10000) -> 31.977774 | H2: =1289+48246 -> 49535 | I2: 42.5 | J2: 82.9 | K2: =IF('Nation Wise Summary'!U2="", "", ('Nation-Wide Education Seg'!H2/'Nation Wise Summary'!U2)*100) -> 1.666054 | L2: =IF('Nation Non-Social Pop Demograph'!B2="", "", ('Nation-Wide Education Seg'!H2/'Nation Non-Social Pop Demograph'!B2)*10000) -> 0.33480053 | M2: =IF('Nation Non-Social Pop Demograph'!N2="", "", ('Nation-Wide Education Seg'!H2/'Nation Non-Social Pop Demograph'!N2)*10000) -> 1.5013477 | N2: 10273020 | O2: 1732000 | P2: =(N2/'Nation Non-Social Pop Demograph'!J2)*10000 -> 223.9806 | Q2: =(O2/'Nation Non-Social Pop Demograph'!N2)*10000 -> 52.494885
A3: China | B3: 97.15 | C3: =(440000+470000)/2 -> 455000 | D3: 32.52 | E3: =IF('Nation Wise Summary'!U3="", "", (C3/'Nation Wise Summary'!U3)*100) -> 4.8465038 | F3: =IF('Nation Non-Social Pop Demograph'!B3="", "", ('Nation-Wide Education Seg'!C3/'Nation Non-Social Pop Demograph'!B3)*10000) -> 3.2220239 | G3: =IF('Nation Non-Social Pop Demograph'!J3="", "", ('Nation-Wide Education Seg'!C3/'Nation Non-Social Pop Demograph'!J3)*10000) -> 15.773964 | H3: 3196 | I3: 25 | J3: 25 | K3: =IF('Nation Wise Summary'!U3="", "", ('Nation-Wide Education Seg'!H3/'Nation Wise Summary'!U3)*100) -> 0.034042695 | L3: =IF('Nation Non-Social Pop Demograph'!B3="", "", ('Nation-Wide Education Seg'!H3/'Nation Non-Social Pop Demograph'!B3)*10000) -> 0.022632062 | M3: =IF('Nation Non-Social Pop Demograph'!N3="", "", ('Nation-Wide Education Seg'!H3/'Nation Non-Social Pop Demograph'!N3)*10000) -> 0.15798319 | N3: 18918000 | O3: 2070000 | P3: =(N3/'Nation Non-Social Pop Demograph'!J3)*10000 -> 655.85023 | Q3: =(O3/'Nation Non-Social Pop Demograph'!N3)*10000 -> 102.32328
A4: United States | B4: 99 | C4: 133573 | D4: 25.83 | E4: =IF('Nation Wise Summary'!U4="", "", (C4/'Nation Wise Summary'!U4)*100) -> 1.4602738 | F4: =IF('Nation Non-Social Pop Demograph'!B4="", "", ('Nation-Wide Education Seg'!C4/'Nation Non-Social Pop Demograph'!B4)*10000) -> 3.8215081 | G4: =IF('Nation Non-Social Pop Demograph'!J4="", "", ('Nation-Wide Education Seg'!C4/'Nation Non-Social Pop Demograph'!J4)*10000) -> 18.546307 | H4: 5626 | I4: 66.22 | J4: 66.22 | K4: =IF('Nation Wise Summary'!U4="", "", ('Nation-Wide Education Seg'!H4/'Nation Wise Summary'!U4)*100) -> 0.061505698 | L4: =IF('Nation Non-Social Pop Demograph'!B4="", "", ('Nation-Wide Education Seg'!H4/'Nation Non-Social Pop Demograph'!B4)*10000) -> 0.16095921 | M4: =IF('Nation Non-Social Pop Demograph'!N4="", "", ('Nation-Wide Education Seg'!H4/'Nation Non-Social Pop Demograph'!N4)*10000) -> 1.0447539 | N4: 4007908 | O4: 1507600 | P4: =(N4/'Nation Non-Social Pop Demograph'!J4)*10000 -> 556.48889 | Q4: =(O4/'Nation Non-Social Pop Demograph'!N4)*10000 -> 279.96286
A5: Indonesia | B5: 96.35 | C5: 236000 | D5: 22 | E5: =IF('Nation Wise Summary'!U5="", "", (C5/'Nation Wise Summary'!U5)*100) -> 13.027381 | F5: =IF('Nation Non-Social Pop Demograph'!B5="", "", ('Nation-Wide Education Seg'!C5/'Nation Non-Social Pop Demograph'!B5)*10000) -> 8.1820335 | G5: =IF('Nation Non-Social Pop Demograph'!J5="", "", ('Nation-Wide Education Seg'!C5/'Nation Non-Social Pop Demograph'!J5)*10000) -> 28.205909 | H5: 4655 | I5: 94.5 | J5: 94.5 | K5: =IF('Nation Wise Summary'!U5="", "", ('Nation-Wide Education Seg'!H5/'Nation Wise Summary'!U5)*100) -> 0.25695957 | L5: =IF('Nation Non-Social Pop Demograph'!B5="", "", ('Nation-Wide Education Seg'!H5/'Nation Non-Social Pop Demograph'!B5)*10000) -> 0.16138714 | M5: =IF('Nation Non-Social Pop Demograph'!N5="", "", ('Nation-Wide Education Seg'!H5/'Nation Non-Social Pop Demograph'!N5)*10000) -> 0.87136614 | N5: 3028300 | O5: 303067 | P5: =(N5/'Nation Non-Social Pop Demograph'!J5)*10000 -> 361.93201 | Q5: =(O5/'Nation Non-Social Pop Demograph'!N5)*10000 -> 56.730896
A6: Pakistan | E6: =IF('Nation Wise Summary'!U6="", "", (C6/'Nation Wise Summary'!U6)*100) | F6: =IF('Nation Non-Social Pop Demograph'!B6="", "", ('Nation-Wide Education Seg'!C6/'Nation Non-Social Pop Demograph'!B6)*10000) -> 0 | G6: =IF('Nation Non-Social Pop Demograph'!J6="", "", ('Nation-Wide Education Seg'!C6/'Nation Non-Social Pop Demograph'!J6)*10000) -> 0 | K6: =IF('Nation Wise Summary'!U6="", "", 'Nation-Wide Education Seg'!H6/'Nation Wise Summary'!U6) | L6: =IF('Nation Non-Social Pop Demograph'!B6="", "", ('Nation-Wide Education Seg'!H6/'Nation Non-Social Pop Demograph'!B6)*10000) -> 0 | M6: =IF('Nation Non-Social Pop Demograph'!N6="", "", ('Nation-Wide Education Seg'!H6/'Nation Non-Social Pop Demograph'!N6)*10000)
A7: Nigeria | E7: =IF('Nation Wise Summary'!U7="", "", (C7/'Nation Wise Summary'!U7)*100) | F7: =IF('Nation Non-Social Pop Demograph'!B7="", "", ('Nation-Wide Education Seg'!C7/'Nation Non-Social Pop Demograph'!B7)*10000) | G7: =IF('Nation Non-Social Pop Demograph'!J7="", "", ('Nation-Wide Education Seg'!C7/'Nation Non-Social Pop Demograph'!J7)*10000) | K7: =IF('Nation Wise Summary'!U7="", "", 'Nation-Wide Education Seg'!H7/'Nation Wise Summary'!U7) | L7: =IF('Nation Non-Social Pop Demograph'!B7="", "", ('Nation-Wide Education Seg'!H7/'Nation Non-Social Pop Demograph'!B7)*10000) | M7: =IF('Nation Non-Social Pop Demograph'!N7="", "", ('Nation-Wide Education Seg'!H7/'Nation Non-Social Pop Demograph'!N7)*10000)
A8: Brazil | E8: =IF('Nation Wise Summary'!U8="", "", (C8/'Nation Wise Summary'!U8)*100) | F8: =IF('Nation Non-Social Pop Demograph'!B8="", "", ('Nation-Wide Education Seg'!C8/'Nation Non-Social Pop Demograph'!B8)*10000) | G8: =IF('Nation Non-Social Pop Demograph'!J8="", "", ('Nation-Wide Education Seg'!C8/'Nation Non-Social Pop Demograph'!J8)*10000) | K8: =IF('Nation Wise Summary'!U8="", "", 'Nation-Wide Education Seg'!H8/'Nation Wise Summary'!U8) | L8: =IF('Nation Non-Social Pop Demograph'!B8="", "", ('Nation-Wide Education Seg'!H8/'Nation Non-Social Pop Demograph'!B8)*10000) | M8: =IF('Nation Non-Social Pop Demograph'!N8="", "", ('Nation-Wide Education Seg'!H8/'Nation Non-Social Pop Demograph'!N8)*10000)
A9: Bangladesh | E9: =IF('Nation Wise Summary'!U9="", "", (C9/'Nation Wise Summary'!U9)*100) | F9: =IF('Nation Non-Social Pop Demograph'!B9="", "", ('Nation-Wide Education Seg'!C9/'Nation Non-Social Pop Demograph'!B9)*10000) | G9: =IF('Nation Non-Social Pop Demograph'!J9="", "", ('Nation-Wide Education Seg'!C9/'Nation Non-Social Pop Demograph'!J9)*10000) | K9: =IF('Nation Wise Summary'!U9="", "", 'Nation-Wide Education Seg'!H9/'Nation Wise Summary'!U9) | L9: =IF('Nation Non-Social Pop Demograph'!B9="", "", ('Nation-Wide Education Seg'!H9/'Nation Non-Social Pop Demograph'!B9)*10000) | M9: =IF('Nation Non-Social Pop Demograph'!N9="", "", ('Nation-Wide Education Seg'!H9/'Nation Non-Social Pop Demograph'!N9)*10000)
A10: Russia | E10: =IF('Nation Wise Summary'!U10="", "", (C10/'Nation Wise Summary'!U10)*100) | F10: =IF('Nation Non-Social Pop Demograph'!B10="", "", ('Nation-Wide Education Seg'!C10/'Nation Non-Social Pop Demograph'!B10)*10000) | G10: =IF('Nation Non-Social Pop Demograph'!J10="", "", ('Nation-Wide Education Seg'!C10/'Nation Non-Social Pop Demograph'!J10)*10000) | K10: =IF('Nation Wise Summary'!U10="", "", 'Nation-Wide Education Seg'!H10/'Nation Wise Summary'!U10) | L10: =IF('Nation Non-Social Pop Demograph'!B10="", "", ('Nation-Wide Education Seg'!H10/'Nation Non-Social Pop Demograph'!B10)*10000) | M10: =IF('Nation Non-Social Pop Demograph'!N10="", "", ('Nation-Wide Education Seg'!H10/'Nation Non-Social Pop Demograph'!N10)*10000)
A11: Ethiopia | E11: =IF('Nation Wise Summary'!U11="", "", (C11/'Nation Wise Summary'!U11)*100) | F11: =IF('Nation Non-Social Pop Demograph'!B11="", "", ('Nation-Wide Education Seg'!C11/'Nation Non-Social Pop Demograph'!B11)*10000) | G11: =IF('Nation Non-Social Pop Demograph'!J11="", "", ('Nation-Wide Education Seg'!C11/'Nation Non-Social Pop Demograph'!J11)*10000) | K11: =IF('Nation Wise Summary'!U11="", "", 'Nation-Wide Education Seg'!H11/'Nation Wise Summary'!U11) | L11: =IF('Nation Non-Social Pop Demograph'!B11="", "", ('Nation-Wide Education Seg'!H11/'Nation Non-Social Pop Demograph'!B11)*10000) | M11: =IF('Nation Non-Social Pop Demograph'!N11="", "", ('Nation-Wide Education Seg'!H11/'Nation Non-Social Pop Demograph'!N11)*10000)
A12: Mexico | E12: =IF('Nation Wise Summary'!U12="", "", (C12/'Nation Wise Summary'!U12)*100) | F12: =IF('Nation Non-Social Pop Demograph'!B12="", "", ('Nation-Wide Education Seg'!C12/'Nation Non-Social Pop Demograph'!B12)*10000) | G12: =IF('Nation Non-Social Pop Demograph'!J12="", "", ('Nation-Wide Education Seg'!C12/'Nation Non-Social Pop Demograph'!J12)*10000) | K12: =IF('Nation Wise Summary'!U12="", "", 'Nation-Wide Education Seg'!H12/'Nation Wise Summary'!U12) | L12: =IF('Nation Non-Social Pop Demograph'!B12="", "", ('Nation-Wide Education Seg'!H12/'Nation Non-Social Pop Demograph'!B12)*10000) | M12: =IF('Nation Non-Social Pop Demograph'!N12="", "", ('Nation-Wide Education Seg'!H12/'Nation Non-Social Pop Demograph'!N12)*10000)
A13: Japan | E13: =IF('Nation Wise Summary'!U13="", "", (C13/'Nation Wise Summary'!U13)*100) | F13: =IF('Nation Non-Social Pop Demograph'!B13="", "", ('Nation-Wide Education Seg'!C13/'Nation Non-Social Pop Demograph'!B13)*10000) | G13: =IF('Nation Non-Social Pop Demograph'!J13="", "", ('Nation-Wide Education Seg'!C13/'Nation Non-Social Pop Demograph'!J13)*10000) | K13: =IF('Nation Wise Summary'!U13="", "", 'Nation-Wide Education Seg'!H13/'Nation Wise Summary'!U13) | L13: =IF('Nation Non-Social Pop Demograph'!B13="", "", ('Nation-Wide Education Seg'!H13/'Nation Non-Social Pop Demograph'!B13)*10000) | M13: =IF('Nation Non-Social Pop Demograph'!N13="", "", ('Nation-Wide Education Seg'!H13/'Nation Non-Social Pop Demograph'!N13)*10000)
A14: Egypt | E14: =IF('Nation Wise Summary'!U14="", "", (C14/'Nation Wise Summary'!U14)*100) | F14: =IF('Nation Non-Social Pop Demograph'!B14="", "", ('Nation-Wide Education Seg'!C14/'Nation Non-Social Pop Demograph'!B14)*10000) | G14: =IF('Nation Non-Social Pop Demograph'!J14="", "", ('Nation-Wide Education Seg'!C14/'Nation Non-Social Pop Demograph'!J14)*10000) | K14: =IF('Nation Wise Summary'!U14="", "", 'Nation-Wide Education Seg'!H14/'Nation Wise Summary'!U14) | L14: =IF('Nation Non-Social Pop Demograph'!B14="", "", ('Nation-Wide Education Seg'!H14/'Nation Non-Social Pop Demograph'!B14)*10000) | M14: =IF('Nation Non-Social Pop Demograph'!N14="", "", ('Nation-Wide Education Seg'!H14/'Nation Non-Social Pop Demograph'!N14)*10000)
A15: Phillipines | E15: =IF('Nation Wise Summary'!U15="", "", (C15/'Nation Wise Summary'!U15)*100) | F15: =IF('Nation Non-Social Pop Demograph'!B15="", "", ('Nation-Wide Education Seg'!C15/'Nation Non-Social Pop Demograph'!B15)*10000) | G15: =IF('Nation Non-Social Pop Demograph'!J15="", "", ('Nation-Wide Education Seg'!C15/'Nation Non-Social Pop Demograph'!J15)*10000) | K15: =IF('Nation Wise Summary'!U15="", "", 'Nation-Wide Education Seg'!H15/'Nation Wise Summary'!U15) | L15: =IF('Nation Non-Social Pop Demograph'!B15="", "", ('Nation-Wide Education Seg'!H15/'Nation Non-Social Pop Demograph'!B15)*10000) | M15: =IF('Nation Non-Social Pop Demograph'!N15="", "", ('Nation-Wide Education Seg'!H15/'Nation Non-Social Pop Demograph'!N15)*10000)
A16: DR Congo | E16: =IF('Nation Wise Summary'!U16="", "", (C16/'Nation Wise Summary'!U16)*100) | F16: =IF('Nation Non-Social Pop Demograph'!B16="", "", ('Nation-Wide Education Seg'!C16/'Nation Non-Social Pop Demograph'!B16)*10000) | G16: =IF('Nation Non-Social Pop Demograph'!J16="", "", ('Nation-Wide Education Seg'!C16/'Nation Non-Social Pop Demograph'!J16)*10000) | K16: =IF('Nation Wise Summary'!U16="", "", 'Nation-Wide Education Seg'!H16/'Nation Wise Summary'!U16) | L16: =IF('Nation Non-Social Pop Demograph'!B16="", "", ('Nation-Wide Education Seg'!H16/'Nation Non-Social Pop Demograph'!B16)*10000) | M16: =IF('Nation Non-Social Pop Demograph'!N16="", "", ('Nation-Wide Education Seg'!H16/'Nation Non-Social Pop Demograph'!N16)*10000)
A17: Vietnam | E17: =IF('Nation Wise Summary'!U17="", "", (C17/'Nation Wise Summary'!U17)*100) | F17: =IF('Nation Non-Social Pop Demograph'!B17="", "", ('Nation-Wide Education Seg'!C17/'Nation Non-Social Pop Demograph'!B17)*10000) | G17: =IF('Nation Non-Social Pop Demograph'!J17="", "", ('Nation-Wide Education Seg'!C17/'Nation Non-Social Pop Demograph'!J17)*10000) | K17: =IF('Nation Wise Summary'!U17="", "", 'Nation-Wide Education Seg'!H17/'Nation Wise Summary'!U17) | L17: =IF('Nation Non-Social Pop Demograph'!B17="", "", ('Nation-Wide Education Seg'!H17/'Nation Non-Social Pop Demograph'!B17)*10000) | M17: =IF('Nation Non-Social Pop Demograph'!N17="", "", ('Nation-Wide Education Seg'!H17/'Nation Non-Social Pop Demograph'!N17)*10000)
... A197: Holy See | E197: =IF('Nation Wise Summary'!U197="", "", (C197/'Nation Wise Summary'!U197)*100) | F197: =IF('Nation Non-Social Pop Demograph'!B197="", "", ('Nation-Wide Education Seg'!C197/'Nation Non-Social Pop Demograph'!B197)*10000) | G197: =IF('Nation Non-Social Pop Demograph'!J197="", "", ('Nation-Wide Education Seg'!C197/'Nation Non-Social Pop Demograph'!J197)*10000) | K197: =IF('Nation Wise Summary'!U197="", "", 'Nation-Wide Education Seg'!H197/'Nation Wise Summary'!U197) | L197: =IF('Nation Non-Social Pop Demograph'!B197="", "", ('Nation-Wide Education Seg'!H197/'Nation Non-Social Pop Demograph'!B197)*10000) | M197: =IF('Nation Non-Social Pop Demograph'!N197="", "", ('Nation-Wide Education Seg'!H197/'Nation Non-Social Pop Demograph'!N197)*10000)

Sheet City Wise Data
A1: City | B1: Nation | C1: Population | D1: Population density | E1: Total Land Area
A2: Kanpur | B2: India
A3: Chongqing | B3: China
A4: Patna | B4: India
A5: New York City | B5: USA
A6: Toronto | B6: Canada
A7: Mumbai | B7: India
A8: Jakarta | B8: Indonesia
A9: Kolkata | B9: India
A10: Lagos | B10: Nigeria
A11: Indore | B11: India
A12: Sao Paulo | B12: Brazil
A13: Sydney | B13: Australia
... A368: Bakutala | B368: India
B369: Singapore
B370: Hungary

Sheet Nation Topography
A1: Nation
A2: ='Nation Wise Summary'!A2 -> India
A3: ='Nation Wise Summary'!A3 -> China
A4: ='Nation Wise Summary'!A4 -> United States
A5: ='Nation Wise Summary'!A5 -> Indonesia
A6: ='Nation Wise Summary'!A6 -> Pakistan
A7: ='Nation Wise Summary'!A7 -> Nigeria
A8: ='Nation Wise Summary'!A8 -> Brazil
A9: ='Nation Wise Summary'!A9 -> Bangladesh
A10: ='Nation Wise Summary'!A10 -> Russia
A11: ='Nation Wise Summary'!A11 -> Ethiopia
A12: ='Nation Wise Summary'!A12 -> Mexico
A13: ='Nation Wise Summary'!A13 -> Japan
... A177: ='Nation Wise Summary'!A177 -> Saint Lucia
A178: ='Nation Wise Summary'!#REF! -> #REF!
A179: ='Nation Wise Summary'!A178 -> Kiribati
A180: ='Nation Wise Summary'!A179 -> Seychelles
A181: ='Nation Wise Summary'!A180 -> Grenada
A182: ='Nation Wise Summary'!A181 -> Micronesia
A183: ='Nation Wise Summary'!A182 -> Tonga
A184: ='Nation Wise Summary'!A183 -> Saint Vincent and Grenadines
A185: ='Nation Wise Summary'!A184 -> Antigua and Barbuda
A186: ='Nation Wise Summary'!#REF! -> #REF!
A187: ='Nation Wise Summary'!A185 -> Andorra
A188: ='Nation Wise Summary'!A186 -> Cayman Islands
A189: ='Nation Wise Summary'!A187 -> Dominica
A190: ='Nation Wise Summary'!A188 -> Bermuda

Sheet City Topography
A1: City | B1: Nation
A2: Kanpur | B2: India
A3: Chongqing | B3: China
A4: Patna | B4: India
A5: New York City | B5: USA
A6: Toronto | B6: Canada
A7: Mumbai | B7: India
A8: Jakarta | B8: Indonesia
A9: Kolkata | B9: India
A10: Lagos | B10: Nigeria
A11: Indore | B11: India
A12: Sao Paulo | B12: Brazil
... A368: Bakutala | B368: India

Sheet Nation-wise source of income
A1: Nation
A2: ='Nation Wise Summary'!A2 -> India
A3: ='Nation Wise Summary'!A3 -> China
A4: ='Nation Wise Summary'!A4 -> United States
A5: ='Nation Wise Summary'!A5 -> Indonesia
A6: ='Nation Wise Summary'!A6 -> Pakistan
A7: ='Nation Wise Summary'!A7 -> Nigeria
A8: ='Nation Wise Summary'!A8 -> Brazil
A9: ='Nation Wise Summary'!A9 -> Bangladesh
A10: ='Nation Wise Summary'!A10 -> Russia
A11: ='Nation Wise Summary'!A11 -> Ethiopia
A12: ='Nation Wise Summary'!A12 -> Mexico
A13: ='Nation Wise Summary'!A13 -> Japan
... A177: ='Nation Wise Summary'!A177 -> Saint Lucia
A178: ='Nation Wise Summary'!#REF! -> #REF!
A179: ='Nation Wise Summary'!A178 -> Kiribati
A180: ='Nation Wise Summary'!A179 -> Seychelles
A181: ='Nation Wise Summary'!A180 -> Grenada
A182: ='Nation Wise Summary'!A181 -> Micronesia
A183: ='Nation Wise Summary'!A182 -> Tonga
A184: ='Nation Wise Summary'!A183 -> Saint Vincent and Grenadines
A185: ='Nation Wise Summary'!A184 -> Antigua and Barbuda
A186: ='Nation Wise Summary'!#REF! -> #REF!
A187: ='Nation Wise Summary'!A185 -> Andorra
A188: ='Nation Wise Summary'!A186 -> Cayman Islands
A189: ='Nation Wise Summary'!A187 -> Dominica
A190: ='Nation Wise Summary'!A188 -> Bermuda

Sheet Nation Wise Cost of Living Data

Sheet City Wise Cost of Living Data

Sheet Nation wise safety index cal
A1: Nation | B1: Form of Governence | C1: Army Rank as of 2026 | D1: Navy Rank as of 2026 | E1: Air Force Rank as of 2026 | F1: Army Personnel in 2026 | G1: Navy Personnel in 2026 | H1: Air Force Personnel in 2026 | I1: Army Weapon Arsenal in 2026 | J1: Navy Weapon Arsenal in 2026 | K1: Air Force Weapon Arsenal in 2026 | L1: Army Rank as of 2025 | M1: Navy Rank as of 2025 | N1: Air Force Rank as of 2025 | O1: Army Personnel in 2025 | P1: Navy Personnel in 2025 | Q1: Air Force Personnel in 2025 | R1: Army Weapon Arsenal in 2025 | S1: Navy Weapon Arsenal in 2025 | T1: Air Force Weapon Arsenal in 2025 | U1: Nuclear Nation | V1: Nuclear Count | W1: Protests in 2025 | X1: Protests in 2024 | Y1: Pending Legal Cases till 2026 | Z1: Theft reported - 2025 | AA1: Theft reported - 2024 | AB1: Murders reported 2025 | AC1: Murders reported 2024 | AD1: Road Accidents in 2025 | AE1: Road Accidents in 2024 | AF1: Rail Accidents in 2025 | AG1: Rail Accidents in 2024 | AH1: Air Accidents in 2025 | AI1: Air Accidents in 2024 | AJ1: Water Accidents in 2025 | AK1: Water Accidents in 2024 | AL1: Accidents due to faulty constructions - 2025 | AM1: Accidents due to faulty constructions - 2024 | AN1: Kidnapping - 2025 | AO1: Kidnapping - 2024 | AP1: Rape and Exploitation-2025 | AQ1: Rape and Exploitation-2024 | AR1: Deaths because of diseases - 2025 | AS1: Deaths because of diseases - 2024 | AT1: Registered Cyber fraud case - 2025 | AU1: Registered Cyber fraud case - 2024 | AV1: Deaths due to disasters in 2025 | AW1: Deaths due to disasters in 2024 | AX1: Deaths due to non-war genocide - 2025 | AY1: Deaths due to non-war genocide - 2024 | AZ1: Smuggled goods captured by authorities - 2025 | BA1: Smuggled goods captured by authorities - 2024 | BB1: Key Smuggled Goods | BC1: Drugs and contrabend related crimes reported - 2025 | BD1: Drugs and contrabend related crimes reported - 2024 | BE1: Miscellaneous crimes - 2025 | BF1: Miscellaneous crimes - 2024 | BG1: Involved in wars or civil wars | BH1: Total Casualities | BI1: Casualities within a year | BJ1: Disputed regions | BK1: Dispute with which Nations
A2: ='Nation Wise Summary'!A2 -> India | B2: ='Nation Wise Summary'!D2 -> Federal Parliamentary Democratic Republic
A3: ='Nation Wise Summary'!A3 -> China | B3: ='Nation Wise Summary'!D3 -> Unitary Socialist One-Party Republic
A4: ='Nation Wise Summary'!A4 -> United States | B4: ='Nation Wise Summary'!D4 -> Federal Constitutional Republic and Representative Democracy
A5: ='Nation Wise Summary'!A5 -> Indonesia | B5: ='Nation Wise Summary'!D5 -> Unitary Presidential Constitutional Republic
A6: ='Nation Wise Summary'!A6 -> Pakistan | B6: ='Nation Wise Summary'!D6 -> Federal Parliamentary Republic
A7: ='Nation Wise Summary'!A7 -> Nigeria | B7: ='Nation Wise Summary'!D7 -> Federal Parliamentary Republic
A8: ='Nation Wise Summary'!A8 -> Brazil | B8: ='Nation Wise Summary'!D8 -> Federal Constitutional Republic and Representative Democracy
A9: ='Nation Wise Summary'!A9 -> Bangladesh | B9: ='Nation Wise Summary'!D9 -> Unitary Parliamentary Representative Democratic Republic
A10: ='Nation Wise Summary'!A10 -> Russia | B10: ='Nation Wise Summary'!D10 -> Federal Semi-Presidential Republic
A11: ='Nation Wise Summary'!A11 -> Ethiopia | B11: ='Nation Wise Summary'!D11 -> Federal Parliamentary Republic
A12: ='Nation Wise Summary'!A12 -> Mexico | B12: ='Nation Wise Summary'!D12 -> Federal Presidential Representative Democratic Republic
A13: ='Nation Wise Summary'!A13 -> Japan | B13: ='Nation Wise Summary'!D13 -> Unitary Constitutional Monarchy with a Parliamentary Democracy
... A177: ='Nation Wise Summary'!A177 -> Saint Lucia | B177: ='Nation Wise Summary'!D177 -> 0
A178: ='Nation Wise Summary'!#REF! -> #REF! | B178: ='Nation Wise Summary'!#REF! -> #REF!
A179: ='Nation Wise Summary'!A178 -> Kiribati | B179: ='Nation Wise Summary'!D178 -> 0
A180: ='Nation Wise Summary'!A179 -> Seychelles | B180: ='Nation Wise Summary'!D179 -> 0
A181: ='Nation Wise Summary'!A180 -> Grenada | B181: ='Nation Wise Summary'!D180 -> 0
A182: ='Nation Wise Summary'!A181 -> Micronesia | B182: ='Nation Wise Summary'!D181 -> 0
A183: ='Nation Wise Summary'!A182 -> Tonga | B183: ='Nation Wise Summary'!D182 -> 0
A184: ='Nation Wise Summary'!A183 -> Saint Vincent and Grenadines | B184: ='Nation Wise Summary'!D183 -> 0
A185: ='Nation Wise Summary'!A184 -> Antigua and Barbuda | B185: ='Nation Wise Summary'!D184 -> 0
A186: ='Nation Wise Summary'!#REF! -> #REF! | B186: ='Nation Wise Summary'!#REF! -> #REF!
A187: ='Nation Wise Summary'!A185 -> Andorra | B187: ='Nation Wise Summary'!D185 -> 0
A188: ='Nation Wise Summary'!A186 -> Cayman Islands | B188: ='Nation Wise Summary'!D186 -> 0
A189: ='Nation Wise Summary'!A187 -> Dominica | B189: ='Nation Wise Summary'!D187 -> 0
A190: ='Nation Wise Summary'!A188 -> Bermuda | B190: ='Nation Wise Summary'!D188 -> 0
