Workbook

Sheet City Introduction
A1: City | B1: Nation | C1: State / Province | D1: National Capital | E1: State / Regional Capital | F1: Total Metropolitan Area | G1: Total Land Area | H1: Total Water Area | I1: Total Urban Area | J1: Total District | K1: Master Plan 2031 | L1: Major Source of Employment | M1: Major Source of Income | N1: Popular Industry - Raw material Extraction | O1: Popular Industry - Agriculture and Animal Husbandary | P1: Popular Industry - Manufacturing, Processing, and Refining | Q1: Key Source of city's GDP | R1: Population | S1: Population Density | T1: Urban Population | U1: Urban Density | V1: Road Length | W1: Public Road Transports available | X1: Tram Track Length | Y1: Metro Length | Z1: Subway Length | AA1: Intracity Rail Lenght | AB1: Intracity Water Area | AC1: Metro Phases Built (before 28-08-2026) | AD1: Residential Localities | AE1: Industrial Localities | AF1: Commercial Localities | AG1: Governed by | AH1: Central, State, and Municipal Ruling Side | AI1: Key Landmarks | AJ1: Key Notes
A2: Kanpur | B2: India | C2: Uttar Pradesh | D2: No | E2: No | F2: 1484 | G2: =F2-H2 -> 1446.9 | H2: =0.025*F2 -> 37.1 | I2: 403.7 | J2: 3155 | K2: 580.78 | L2: Manufacturing | M2: Sevices and Manufacturing | N2: NA | O2: Potato, Wheat, Rice, Bovine Milk and Meat, Leather | P2: Leather and Footwear; Industrial and Polymer Machinery; Defence Production; FMCG & Detergents; Synthetic and Hosiery Processing; Industrial Packaging; Flour, Pulse, Oil Mills; Sugar Derivative Processing | Q2: Leather, FMCG and Chemical, Logistics | R2: 4398000 | S2: 9800 | T2: 3016000 | U2: 10650 | AA2: =IF(OR(Y2="", Z2=""), "", Y2+Z2) | AG2: Indian Centre, Uttar Pradesh State, and Kanpur Municipal | AH2: Centre - BJP, State - BJP, Local - | AI2: Nana Rao Park, Kanpur Memorial Church, Bithoor, Moti Jheel, Baba Anadeshwar mandir, ISCON Kanpur, JK Temple, Kanpur Zoological Park, Valmiki Ashram Temple, Green Park Stadium, Brahmavart Ghat, Satti Chaura ghat, Dhruv Teela, Bhitargaon Temple, Clock Tower | AJ2: 1. Urban Density is in the city is between 9800-11500. City Core - the older, central parts of kanpur are the most crowded ones, holding over 30000 residents per sq km, while the newer outer areas are less crowded, averaging about 5600 people per sq km. 2. While average rural density of the city sits close to 587 people per sq km the outer rural regions has only 47.2 people per sq km. 3. Based on the official property tax records and Geographic Information System (GIS) surveys managed by KMC, the total number of assessed buildings and structures in Kanpur is approximately 4.5 to 6.2 Lakhs. Out of total buildings, residential covers 370000 - 530000, commercial - 60000-75000, and industrial - 17500-20000.
A3: Chongqing | B3: China | C3: Federal | AA3: =IF(OR(Y3="", Z3=""), "", Y3+Z3)
A4: Patna | B4: India | C4: Bihar | AA4: =IF(OR(Y4="", Z4=""), "", Y4+Z4)
A5: New York City | B5: USA | C5: New York | AA5: =IF(OR(Y5="", Z5=""), "", Y5+Z5)
A6: Toronto | B6: Canada | C6: Ontario
A7: Mumbai | B7: India | C7: Maharashtra | AA7: =IF(OR(Y7="", Z7=""), "", Y7+Z7)
A8: Jakarta | B8: Indonesia | AA8: =IF(OR(Y8="", Z8=""), "", Y8+Z8)
A9: Kolkata | B9: India | C9: West Bengal | AA9: =IF(OR(Y9="", Z9=""), "", Y9+Z9) | AJ9: 1. The Kolkata Urban Aggolomeration includes Kolkata and Howrah wih other suburbs
A10: Lagos | B10: Nigeria | AA10: =IF(OR(Y10="", Z10=""), "", Y10+Z10)
A11: Indore | B11: India | C11: Madhya Pradesh | AA11: =IF(OR(Y11="", Z11=""), "", Y11+Z11)
A12: Sao Paulo | B12: Brazil | AA12: =IF(OR(Y12="", Z12=""), "", Y12+Z12)
A13: Sydney | B13: Australia
A14: Jaipur | B14: India | C14: Rajasthan | O14: Pearl Millet. | AA14: =IF(OR(Y14="", Z14=""), "", Y14+Z14)
A15: Dhaka | B15: Bangladesh | O15: Rice, | AA15: =IF(OR(Y15="", Z15=""), "", Y15+Z15)
A16: Chennai | B16: India | C16: Tamil Nadu | AA16: =IF(OR(Y16="", Z16=""), "", Y16+Z16)
A17: Moscow | B17: Russia | AA17: =IF(OR(Y17="", Z17=""), "", Y17+Z17)
A18: Amsterdam | B18: Netherlands
A19: Ahmedabad | B19: India | C19: Gujarat | AA19: =IF(OR(Y19="", Z19=""), "", Y19+Z19)
A20: Addis Ababa | B20: Ethiopia | AA20: =IF(OR(Y20="", Z20=""), "", Y20+Z20)
A21: Bengaluru | B21: India | C21: Karnataka | O21: Finger Millet, | AA21: =IF(OR(Y21="", Z21=""), "", Y21+Z21)
A22: Mexico City | B22: Mexico | AA22: =IF(OR(Y22="", Z22=""), "", Y22+Z22) | AJ22: 1. Locally known as Ciudad de Mexico
A23: Dubai | B23: UAE
A24: Visakhapatnam | B24: India | C24: Andhra Pradesh | AA24: =IF(OR(Y24="", Z24=""), "", Y24+Z24)
A25: Tokyo | B25: Japan | C25: Tokya
A26: Bhubaneshwar | B26: India | C26: Odisha | AA26: =IF(OR(Y26="", Z26=""), "", Y26+Z26)
A27: Cairo | B27: Egypt
A28: Zurich | B28: Switzerland
A29: Hyderabad | B29: India | C29: Telangana | AA29: =IF(OR(Y29="", Z29=""), "", Y29+Z29)
A30: Quezon City | B30: Philippines | C30: Federal
A31: Thiruvananthapuram | B31: India | C31: Kerala | AA31: =IF(OR(Y31="", Z31=""), "", Y31+Z31)
A32: Kinshasa | B32: DR Congo
A33: Brussels | B33: Belgium
A34: Jamshedpur | B34: India | C34: Jharkhand | AA34: =IF(OR(Y34="", Z34=""), "", Y34+Z34)
A35: Ho Chi Minh City | B35: Vietnam
A36: Guwahati | B36: India | C36: Assam | AA36: =IF(OR(Y36="", Z36=""), "", Y36+Z36)
A37: Tehran | B37: Iran
A38: Jerusalem | B38: Israel
A39: Ludhiana | B39: India | C39: Punjab | AA39: =IF(OR(Y39="", Z39=""), "", Y39+Z39)
A40: Istanbul | B40: Turkey
...

Sheet City Geography and Topography
A1: City | B1: Nations | C1: State / Province
A2: ='City Introduction'!A2 -> Kanpur | B2: ='City Introduction'!B2 -> India | C2: ='City Introduction'!C2 -> Uttar Pradesh
A3: ='City Introduction'!A3 -> Chongqing | B3: ='City Introduction'!B3 -> China | C3: ='City Introduction'!C3 -> Federal
A4: ='City Introduction'!A4 -> Patna | B4: ='City Introduction'!B4 -> India | C4: ='City Introduction'!C4 -> Bihar
A5: ='City Introduction'!A5 -> New York City | B5: ='City Introduction'!B5 -> USA | C5: ='City Introduction'!C5 -> New York
A6: ='City Introduction'!A7 -> Mumbai | B6: ='City Introduction'!B7 -> India | C6: ='City Introduction'!C7 -> Maharashtra
A7: ='City Introduction'!A8 -> Jakarta | B7: ='City Introduction'!B8 -> Indonesia | C7: ='City Introduction'!C8 -> 0
A8: ='City Introduction'!A9 -> Kolkata | B8: ='City Introduction'!B9 -> India | C8: ='City Introduction'!C9 -> West Bengal
A9: ='City Introduction'!A10 -> Lagos | B9: ='City Introduction'!B10 -> Nigeria | C9: ='City Introduction'!C10 -> 0
A10: ='City Introduction'!A11 -> Indore | B10: ='City Introduction'!B11 -> India | C10: ='City Introduction'!C11 -> Madhya Pradesh
A11: ='City Introduction'!A12 -> Sao Paulo | B11: ='City Introduction'!B12 -> Brazil | C11: ='City Introduction'!C12 -> 0
A12: ='City Introduction'!A14 -> Jaipur | B12: ='City Introduction'!B14 -> India | C12: ='City Introduction'!C14 -> Rajasthan
A13: ='City Introduction'!A15 -> Dhaka | B13: ='City Introduction'!B15 -> Bangladesh | C13: ='City Introduction'!C15 -> 0
A14: ='City Introduction'!A16 -> Chennai | B14: ='City Introduction'!B16 -> India | C14: ='City Introduction'!C16 -> Tamil Nadu
A15: ='City Introduction'!A17 -> Moscow | B15: ='City Introduction'!B17 -> Russia | C15: ='City Introduction'!C17 -> 0
A16: ='City Introduction'!A19 -> Ahmedabad | B16: ='City Introduction'!B19 -> India | C16: ='City Introduction'!C19 -> Gujarat
A17: ='City Introduction'!A20 -> Addis Ababa | B17: ='City Introduction'!B20 -> Ethiopia | C17: ='City Introduction'!C20 -> 0
A18: ='City Introduction'!A21 -> Bengaluru | B18: ='City Introduction'!B21 -> India | C18: ='City Introduction'!C21 -> Karnataka
A19: ='City Introduction'!A22 -> Mexico City | B19: ='City Introduction'!B22 -> Mexico | C19: ='City Introduction'!C22 -> 0
A20: ='City Introduction'!A24 -> Visakhapatnam | B20: ='City Introduction'!B24 -> India | C20: ='City Introduction'!C24 -> Andhra Pradesh
A21: ='City Introduction'!A25 -> Tokyo | B21: ='City Introduction'!B25 -> Japan | C21: ='City Introduction'!C25 -> Tokya
A22: ='City Introduction'!A26 -> Bhubaneshwar | B22: ='City Introduction'!B26 -> India | C22: ='City Introduction'!C26 -> Odisha
A23: ='City Introduction'!A27 -> Cairo | B23: ='City Introduction'!B27 -> Egypt | C23: ='City Introduction'!C27 -> 0
A24: ='City Introduction'!A29 -> Hyderabad | B24: ='City Introduction'!B29 -> India | C24: ='City Introduction'!C29 -> Telangana
A25: ='City Introduction'!A30 -> Quezon City | B25: ='City Introduction'!B30 -> Philippines | C25: ='City Introduction'!C30 -> Federal
A26: ='City Introduction'!A31 -> Thiruvananthapuram | B26: ='City Introduction'!B31 -> India | C26: ='City Introduction'!C31 -> Kerala
A27: ='City Introduction'!A32 -> Kinshasa | B27: ='City Introduction'!B32 -> DR Congo | C27: ='City Introduction'!C32 -> 0
A28: ='City Introduction'!A34 -> Jamshedpur | B28: ='City Introduction'!B34 -> India | C28: ='City Introduction'!C34 -> Jharkhand
A29: ='City Introduction'!A35 -> Ho Chi Minh City | B29: ='City Introduction'!B35 -> Vietnam | C29: ='City Introduction'!C35 -> 0
A30: ='City Introduction'!A36 -> Guwahati | B30: ='City Introduction'!B36 -> India | C30: ='City Introduction'!C36 -> Assam
A31: ='City Introduction'!A39 -> Ludhiana | B31: ='City Introduction'!B39 -> India | C31: ='City Introduction'!C39 -> Punjab
A32: ='City Introduction'!A41 -> Raipur | B32: ='City Introduction'!B41 -> India | C32: ='City Introduction'!C41 -> Chattisgarh
A33: ='City Introduction'!A44 -> Faridabad | B33: ='City Introduction'!B44 -> India | C33: ='City Introduction'!C44 -> Haryana
A34: ='City Introduction'!A46 -> Delhi | B34: ='City Introduction'!B46 -> India | C34: ='City Introduction'!C46 -> Delhi
A35: ='City Introduction'!A49 -> Srinagar | B35: ='City Introduction'!B49 -> India | C35: ='City Introduction'!C49 -> Jammu and Kashmir
A36: ='City Introduction'!A51 -> Dehradun | B36: ='City Introduction'!B51 -> India | C36: ='City Introduction'!C51 -> Uttarakhand
A37: ='City Introduction'!A53 -> Shimla | B37: ='City Introduction'!B53 -> India | C37: ='City Introduction'!C53 -> Himachal Pradesh
A38: ='City Introduction'!A55 -> Agartala | B38: ='City Introduction'!B55 -> India | C38: ='City Introduction'!C55 -> Tripura
A39: ='City Introduction'!A57 -> Shillong | B39: ='City Introduction'!B57 -> India | C39: ='City Introduction'!C57 -> Meghalaya
A40: ='City Introduction'!A59 -> Imphal | B40: ='City Introduction'!B59 -> India | C40: ='City Introduction'!C59 -> Manipur
...

Sheet City Demographic
